Workbook

Sheet Index
B2: Britannia Industries LTD
B3: Financial Statement Model & DCF Valuation----Index
B4: BSE: 500825 | NSE: BRITANNIA | ISIN: INE216A01030 | Currency: All figures in ₹ Crore unless stated (Comps in ₹ Crore)
B6: Sheet | C6: Content
B8: Summary | C8: Investment Summary - Output from different valuation methods
B9: Assumptions | C9: Written Assumptions and interpretation behind every forecast driver
B10: Data Sheet | C10: Audited Statement of P/L, B/S, and CFS, FY2022-FY2026
B11: Model | C11: 10-year forecast (FY27E-FY36E): ratios, 3-statement model, working capital, historical
C12: & forecast FCFF, DCF valuation, sensitivity analysis, and Comps analysis
B13: Comps Data | C13: All the input of Trading comparables
B14: Ratio Analysis | C14: Profitability ratios, Dupont/earning power, Liquidity, solvency, Activity ratios
B15: Market Return | C15: Daily Nifty 50 index closing prices used to derive the equity market return for CAPM
B16: Beta & WACC | C16: Cost of capital build-up: peer beta unlevering/relevering, cost of debt, cost of equity (CAPM)
B17: Beta from Regression | C17: Monthly regression of Britannia Industries stock returns vs Nifty 50 (5-year raw beta)

Sheet Summary
B2: Britannia Industries Limited - Investment Summary
B3: BSE: 500825 | NSE: BRITANNIA | ISIN: INE216 A01030 | Sector: FMCG | Industry: Packaged Foods
D5: Equity Value available
B6: Valuation Methods | C6: Enterprise Value | D6: for equity share holders | E6: Value per share | F6: Market Price | G6: Discount/Premium | H6: Discount/Premium% | I6: Interpretation
B7: Discounted Cash Flow - Perpetuity Growth | C7: =Model!H181 -> 69879.088 | D7: =Model!H183 -> 73217.208 | E7: =Model!H185 -> 3039.3196 | F7: ='Comps Data'!D4 -> 4937.5 | G7: =E7-F7 -> -1898.1804 | H7: =G7/F7 -> -0.38444161 | I7: =IF(H7>0,"Undervalued","Overvalued") -> Overvalued
B8: Discounted Cash Flow - Exit Multiple | C8: =Model!I181 -> 100686.65 | D8: =Model!I183 -> 104024.77 | E8: =Model!I185 -> 4318.1721 | F8: =F7 -> 4937.5 | G8: =E8-F8 -> -619.32792 | H8: =G8/F8 -> -0.1254335 | I8: =IF(H8>0,"Undervalued","Overvalued") -> Overvalued
B9: Relative Valuation - EV/EBITDA | C9: =Model!D150 -> 103008.38 | D9: =Model!F150 -> 101980.54 | E9: =Model!H150 -> 4233.3143 | F9: =F8 -> 4937.5 | G9: =E9-F9 -> -704.18571 | H9: =G9/F9 -> -0.14261989 | I9: =IF(H9>0,"Undervalued","Overvalued") -> Overvalued
B10: Relative Valuation - EV/Sales | C10: =Model!D149 -> 65464.713 | D10: =Model!F149 -> 64436.873 | E10: =Model!H149 -> 2674.839 | F10: =F9 -> 4937.5 | G10: =E10-F10 -> -2262.661 | H10: =G10/F10 -> -0.45826045 | I10: =IF(H10>0,"Undervalued","Overvalued") -> Overvalued
B11: Relative Valuation - Price/Earnings | C11: =Model!D151 -> 136698.3 | D11: =Model!F151 -> 135670.46 | E11: =Model!H151 -> 5631.8165 | F11: =F10 -> 4937.5 | G11: =E11-F11 -> 694.31648 | H11: =G11/F11 -> 0.14062106 | I11: =IF(H11>0,"Undervalued","Overvalued") -> Undervalued

Sheet Assumptions 
A1: BRITANNIA INDUSTRIES LTD
A3: ASSUMPTIONS
C5: COLOUR CODE
C6: Input / hard-coded figure | D6: Blue
C7: Calculated figure | D7: Black
C10: Ratio Assumption
C11: Revenue growth (Base / Bull / Bear) | D11: Base case starts at the FY23-FY26 average growth (7.98%) in FY27E. Bull uses the highest historical growth (15.31%) and Bear the lowest (2.88%). Growth tapers down 3% each year (multiplicative) over FY27E-FY36E, so Base fades from 7.98% to about 6.07% by FY36E. Scenario is selected with the switch in Model!D23 (1 = Base, 2 = Bull, 3 = Bear).
C12: Cost ratios (COGS, Salaries, Other SG&A, % of revenue) | D12: Held constant for all 10 forecast years at the simple average of the five audited years (FY22-FY26): COGS 58.93%, Salaries & benefits 4.07%, Other SG&A 19.38%. A fixed average avoids blending forecast years into later averages and smooths the FY23-FY24 commodity-price swings.
C13: Depreciation (% of opening PP&E) | D13: Average of FY23-FY26 rates (11.25%), held constant. FY22 is excluded because opening PP&E for FY22 is not available in the model.
C14: Interest rate on debt | D14: Average of FY23-FY26 interest / opening debt (7.01%), held constant. Debt is kept flat at the FY26 level (Rs 1,380.28 Cr), with no new issuance or repayment, since Britannia's borrowings are small relative to its equity value.
C15: Other income (% of revenue) | D15: Average of FY22-FY26 (1.71%), held constant. This includes the FY23 spike (3.66%), so it is slightly generous versus the last three years (about 1.0-1.2%).
C16: Tax rate | D16: Average effective tax rate of FY22-FY26 (25.17%) is used in the P&L forecast. The DCF uses the latest tax rate from the comps data (22.89%) for cash tax and for the WACC tax shield.
C17: Dividend payout ratio | D17: Average of FY22-FY26 (91.21%), held constant. This is high because of the special/higher payout years, and it keeps cash from building up excessively on the balance sheet.
C18: Working capital (receivable / inventory / payable days) | D18: Average of the five audited years, held constant: receivable days 8.51, inventory days 46.90, payable days 59.06. Applied to forecast revenue (receivables) and COGS (inventory, payables). The change in working capital each year flows into cash flow and FCFF with the same sign convention as the cash flow statement.
C19: Capital asset turnover / Capex | D19: Capital asset turnover (revenue / PP&E) is the five-year average of 6.42x, held constant. Capex is solved as the increase in revenue divided by this turnover, so capex rises with growth.
C20: Other balance sheet items | D20: Bank deposits, other current assets, goodwill, financial assets, investments in associates, other non-current items, other liabilities, share capital and non-controlling interest are held flat at FY26 levels.
C21: WACC | D21: Constructed using CAPM. Cost of equity = risk-free rate + adjusted beta x equity risk premium. Beta is unlevered for the comparable companies (Nestle India, Gopal Snacks, Bikiaji Foods, The Bombay Burmah, Mrs Bectors) and then relevered according to Britannia’s specific capital structure (levered beta 0.42). The cost of debt before tax is 7.01% (5.41% after tax). WACC combines both at Britannia’s debt/capital ratio of 1.15%, resulting in approximately 8.98%.
C22: Perpetual growth rate | D22: 4.5%, reflecting long-run inflation plus modest real growth for a mature packaged foods business. It is below India's long-run nominal GDP growth and below FY36E base revenue growth of about 6.07%. It also stays well below the risk-free rate (7.12%) and WACC (8.98%), so the terminal value is not aggressive.
... C26: Equity Value Bridge | D26: Equity value = EV − net debt (borrowings and leases, less cash, bank deposits and financial assets) − non-controlling interest + investment in associates & JV, all as at 31 March 2026. Value per share uses 24.09 Cr shares.
C27: Some important calculation terms
C28: Risk Free Rate | D28: 7.12%, taken from the 10-year Government of India bond yield.
C29: Equity Market Return | D29: 11.61%, calculated on the Market Return sheet from daily Nifty 50 closing prices.
C30: Equity Risk Premium | D30: 4.49%, calculated as market return minus risk-free rate.

Sheet Data Sheet
B2: Britannia Industries Ltd
B3: (All figures are in ₹ Crore, Except per share)
A4: # | B4: Income Statement | C4: 2022 | D4: =C4+1 -> 2023 | E4: =D4+1 -> 2024 | F4: =E4+1 -> 2025 | G4: =F4+1 -> 2026
B6: I Revenue from operations
B7: Sale of goods / Income from operations | C7: 13944.67 | D7: 15984.9 | E7: 16546.21 | F7: 17535.02 | G7: 18858.21
B8: Other operating revenues | C8: 191.59 | D8: 315.65 | E8: 223.06 | F8: 407.65 | G8: 293.38
B9: Total | C9: =SUM(C7:C8) -> 14136.26 | D9: =SUM(D7:D8) -> 16300.55 | E9: =SUM(E7:E8) -> 16769.27 | F9: =SUM(F7:F8) -> 17942.67 | G9: =SUM(G7:G8) -> 19151.59
B10: II Other income | C10: 222.83 | D10: 215.86 | E10: 214.18 | F10: 227.09 | G10: 224.03
B11: III Total income (I+II) | C11: =SUM(C9:C10) -> 14359.09 | D11: =SUM(D9:D10) -> 16516.41 | E11: =SUM(E9:E10) -> 16983.45 | F11: =SUM(F9:F10) -> 18169.76 | G11: =SUM(G9:G10) -> 19375.62
B12: IV Expenses
B13: Cost of materials consumed | C13: 7473.97 | D13: 8326.7 | E13: 8546.89 | F13: 9859.45 | G13: 10350.02
B14: Purchases of stock-in-trade | C14: 1361.59 | D14: 1337.13 | E14: 941.48 | F14: 809.35 | G14: 805.23
B15: Changes in inventories of finished goods, work-in-progress and stock-in-trade | C15: -75.26 | D15: -72.53 | E15: 3.66 | F15: -64.75 | G15: -22.37
B16: Employee benefits expense | C16: 542.26 | D16: 658.38 | E16: 708.7 | F16: 704.59 | G16: 823.8
B17: Finance costs | C17: 144.29 | D17: 169.1 | E17: 164 | F17: 138.8 | G17: 112.76
B18: Depreciation and amortisation expense | C18: 200.54 | D18: 225.91 | E18: 300.46 | F18: 313.34 | G18: 336.83
B19: Other expenses | C19: 2632.19 | D19: 3219.96 | E19: 3398.7 | F19: 3446.88 | G19: 3650.48
B20: Total expenses | C20: =SUM(C13:C19) -> 12279.58 | D20: =SUM(D13:D19) -> 13864.65 | E20: =SUM(E13:E19) -> 14063.89 | F20: =SUM(F13:F19) -> 15207.66 | G20: =SUM(G13:G19) -> 16056.75
B21: V Profit before share of profits / (loss) of associates (III-IV) | C21: =C11-C20 -> 2079.51 | D21: 2651.76 | E21: 2919.56 | F21: 2962.1 | G21: 3318.87
B22: VI Share of profit / (loss) of associates | C22: -0.2 | D22: 5.41 | E22: -3.19 | F22: -10.74 | G22: -30.09
B23: VII Profit before exceptional items and tax (V+VI) | C23: 2079.31 | D23: 2657.17 | E23: 2916.37 | F23: 2951.36 | G23: 3288.78
B24: VIII Exceptional items (Refer Note 54) | C24: 0.98 | D24: -375.6 | E24: 2.9 | F24: 24.79
B25: IX Profit before tax (VII-VIII) | C25: 2078.33 | D25: 3032.77 | E25: 2913.47 | F25: 2926.57 | G25: 3288.78
B26: X Tax expense:
B27: (i) Current tax | C27: 612.24 | D27: 720.97 | E27: 765.69 | F27: 741.68 | G27: 758.37
B28: (ii) Deferred tax | C28: -49.89 | D28: -4.52 | E28: 13.56 | F28: 7.03 | G28: -6.6
B29: Total Tax | C29: 562.35 | D29: 716.45 | E29: 779.25 | F29: 748.71 | G29: 751.77
B30: XI Profit for the year (IX-X) | C30: =C25-C29 -> 1515.98 | D30: =D25-D29 -> 2316.32 | E30: =E25-E29 -> 2134.22 | F30: =F25-F29 -> 2177.86 | G30: =G25-G29 -> 2537.01
B32: Basic Shares Outstanding | C32: 24.08683 | D32: 24.08683 | E32: 24.08683 | F32: 24.08683 | G32: 24.08683
B33: Diluted Shares Outstanding | C33: 24.08683 | D33: 24.08683 | E33: 24.08683 | F33: 24.08683 | G33: 24.08683
B35: Basic EPS | C35: 63.31 | D35: 96.39 | E35: 88.84 | F35: 90.45 | G35: 105.18
B36: Diluted EPS | C36: 63.31 | D36: 96.39 | E36: 88.84 | F36: 90.45 | G36: 105.18
A39: # | B39: Balance Sheet | C39: 2022 | D39: =C39+1 -> 2023 | E39: =D39+1 -> 2024 | F39: =E39+1 -> 2025 | G39: =F39+1 -> 2026
B41: Assets
B42: Non-current assets
B43: (a) Property, plant and equipment | C43: 1584.05 | D43: 2472.19 | E43: 2602.94 | F43: 2734.61 | G43: 2672.98
B44: (b) Capital work-in-progress | C44: 535.68 | D44: 105 | E44: 187.54 | F44: 89.2 | G44: 39.04
B45: (c) Investment property | C45: 13.95 | D45: 40.63 | E45: 27.48 | F45: 28.9 | G45: 27.9
B46: (d) Goodwill | C46: 139.61 | D46: 128.16 | E46: 129.82 | F46: 132.78 | G46: 143.95
B47: (e) Other intangible assets | C47: 15.6 | D47: 14.24 | E47: 10.9 | F47: 7.51 | G47: 5.09
...

Sheet Model
B2: ='Data Sheet'!B2 -> Britannia Industries Ltd
B3: Financial Statement & DCF Analysis | C3: 2022 | D3: =C3+1 -> 2023 | E3: =D3+1 -> 2024 | F3: =E3+1 -> 2025 | G3: =F3+1 -> 2026 | H3: =G3+1 -> 2027 | I3: =H3+1 -> 2028 | J3: =I3+1 -> 2029 | K3: =J3+1 -> 2030 | ... Q3: =P3+1 -> 2036
B4: (All figures are in ₹ Crore, Except per share)
A5: # | B5: Income Statement
B7: Revenue | C7: ='Data Sheet'!C9 -> 14136.26 | D7: ='Data Sheet'!D9 -> 16300.55 | E7: ='Data Sheet'!E9 -> 16769.27 | F7: ='Data Sheet'!F9 -> 17942.67 | G7: ='Data Sheet'!G9 -> 19151.59 | H7: =G7*(1+H24) -> 20679.92 | I7: =H7*(1+I24) -> 22280.705 | J7: =I7*(1+J24) -> 23953.661 | K7: =J7*(1+K24) -> 25698.276 | L7: =K7*(1+L24) -> 27513.805 | M7: =L7*(1+M24) -> 29399.284 | N7: =M7*(1+N24) -> 31353.531 | O7: =N7*(1+O24) -> 33375.157 | ... Q7: =P7*(1+Q24) -> 37614.011
B8: COGS | C8: =-SUM('Data Sheet'!C13:C15) -> -8760.3 | D8: =-SUM('Data Sheet'!D13:D15) -> -9591.3 | E8: =-SUM('Data Sheet'!E13:E15) -> -9492.03 | F8: =-SUM('Data Sheet'!F13:F15) -> -10604.05 | G8: =-SUM('Data Sheet'!G13:G15) -> -11132.88 | H8: =-H7*H25 -> -12186.446 | I8: =-I7*I25 -> -13129.771 | J8: =-J7*J25 -> -14115.625 | K8: =-K7*K25 -> -15143.707 | L8: =-L7*L25 -> -16213.578 | M8: =-M7*M25 -> -17324.67 | N8: =-N7*N25 -> -18476.286 | O8: =-O7*O25 -> -19667.608 | ... Q8: =-Q7*Q25 -> -22165.517
B9: Gross Profit | C9: =SUM(C7:C8) -> 5375.96 | D9: =SUM(D7:D8) -> 6709.25 | E9: =SUM(E7:E8) -> 7277.24 | F9: =SUM(F7:F8) -> 7338.62 | G9: =SUM(G7:G8) -> 8018.71 | H9: =SUM(H7:H8) -> 8493.4739 | I9: =SUM(I7:I8) -> 9150.934 | J9: =SUM(J7:J8) -> 9838.036 | ... Q9: =SUM(Q7:Q8) -> 15448.494
B10: Salaries & Benefits | C10: =-'Data Sheet'!C16 -> -542.26 | D10: =-'Data Sheet'!D16 -> -658.38 | E10: =-'Data Sheet'!E16 -> -708.7 | F10: =-'Data Sheet'!F16 -> -704.59 | G10: =-'Data Sheet'!G16 -> -823.8 | H10: =-H7*H26 -> -840.82508 | I10: =-I7*I26 -> -905.9114 | J10: =-J7*J26 -> -973.93217 | K10: =-K7*K26 -> -1044.8665 | L10: =-L7*L26 -> -1118.6841 | M10: =-M7*M26 -> -1195.3458 | N10: =-N7*N26 -> -1274.8035 | O10: =-O7*O26 -> -1357.0009 | ... Q10: =-Q7*Q26 -> -1529.3484
B11: Other SG&A Expenses | C11: =-'Data Sheet'!C19 -> -2632.19 | D11: =-'Data Sheet'!D19 -> -3219.96 | E11: =-'Data Sheet'!E19 -> -3398.7 | F11: =-'Data Sheet'!F19 -> -3446.88 | G11: =-'Data Sheet'!G19 -> -3650.48 | H11: =-H7*H27 -> -4008.2956 | I11: =-I7*I27 -> -4318.5685 | J11: =-J7*J27 -> -4642.8301 | K11: =-K7*K27 -> -4980.9808 | L11: =-L7*L27 -> -5332.8767 | M11: =-M7*M27 -> -5698.3305 | N11: =-N7*N27 -> -6077.1134 | O11: =-O7*O27 -> -6468.9561 | ... Q11: =-Q7*Q27 -> -7290.5539
B12: EBITDA | C12: =SUM(C9:C11) -> 2201.51 | D12: =SUM(D9:D11) -> 2830.91 | E12: =SUM(E9:E11) -> 3169.84 | F12: =SUM(F9:F11) -> 3187.15 | G12: =SUM(G9:G11) -> 3544.43 | H12: =SUM(H9:H11) -> 3644.3532 | I12: =SUM(I9:I11) -> 3926.4541 | J12: =SUM(J9:J11) -> 4221.2737 | ... Q12: =SUM(Q9:Q11) -> 6628.5913
B13: Depreciation & Amortization | C13: =-'Data Sheet'!C18 -> -200.54 | D13: =-'Data Sheet'!D18 -> -225.91 | E13: =-'Data Sheet'!E18 -> -300.46 | F13: =-'Data Sheet'!F18 -> -313.34 | G13: =-'Data Sheet'!G18 -> -336.83 | H13: =-H109*H28 -> -308.18661 | I13: =-I109*I28 -> -300.31315 | J13: =-J109*J28 -> -294.59541 | K13: =-K109*K28 -> -290.78597 | L13: =-L109*L28 -> -288.66117 | M13: =-M109*M28 -> -288.01849 | N13: =-N109*N28 -> -288.67431 | O13: =-O109*O28 -> -290.46186 | ... Q13: =-Q109*Q28 -> -296.83915
B14: EBIT | C14: =SUM(C12:C13) -> 2000.97 | D14: =SUM(D12:D13) -> 2605 | E14: =SUM(E12:E13) -> 2869.38 | F14: =SUM(F12:F13) -> 2873.81 | G14: =SUM(G12:G13) -> 3207.6 | H14: =SUM(H12:H13) -> 3336.1666 | I14: =SUM(I12:I13) -> 3626.1409 | J14: =SUM(J12:J13) -> 3926.6783 | ... Q14: =SUM(Q12:Q13) -> 6331.7522
B15: Interest Expense | C15: =-'Data Sheet'!C17 -> -144.29 | D15: =-'Data Sheet'!D17 -> -169.1 | E15: =-'Data Sheet'!E17 -> -164 | F15: =-'Data Sheet'!F17 -> -138.8 | G15: =-'Data Sheet'!G17 -> -112.76 | H15: =H118 -> -96.807492 | I15: =I118 -> -96.807492 | J15: =J118 -> -96.807492 | K15: =K118 -> -96.807492 | L15: =L118 -> -96.807492 | M15: =M118 -> -96.807492 | N15: =N118 -> -96.807492 | O15: =O118 -> -96.807492 | ... Q15: =Q118 -> -96.807492
B16: Other income | C16: ='Data Sheet'!C10+'Data Sheet'!C22-'Data Sheet'!C24 -> 221.65 | D16: ='Data Sheet'!D10+'Data Sheet'!D22-'Data Sheet'!D24 -> 596.87 | E16: ='Data Sheet'!E10+'Data Sheet'!E22-'Data Sheet'!E24 -> 208.09 | F16: ='Data Sheet'!F10+'Data Sheet'!F22-'Data Sheet'!F24 -> 191.56 | G16: ='Data Sheet'!G10+'Data Sheet'!G22-'Data Sheet'!G24 -> 193.94 | H16: =H7*H30 -> 353.65931 | I16: =I7*I30 -> 381.03525 | J16: =J7*J30 -> 409.64546 | K16: =K7*K30 -> 439.48112 | L16: =L7*L30 -> 470.52954 | M16: =M7*M30 -> 502.7742 | N16: =N7*N30 -> 536.19492 | O16: =O7*O30 -> 570.76792 | ... Q16: =Q7*Q30 -> 643.25901
B17: EBT | C17: =SUM(C14:C16) -> 2078.33 | D17: =SUM(D14:D16) -> 3032.77 | E17: =SUM(E14:E16) -> 2913.47 | F17: =SUM(F14:F16) -> 2926.57 | G17: =SUM(G14:G16) -> 3288.78 | H17: =SUM(H14:H16) -> 3593.0184 | I17: =SUM(I14:I16) -> 3910.3687 | J17: =SUM(J14:J16) -> 4239.5162 | ... Q17: =SUM(Q14:Q16) -> 6878.2037
B18: Tax | C18: =-'Data Sheet'!C29 -> -562.35 | D18: =-'Data Sheet'!D29 -> -716.45 | E18: =-'Data Sheet'!E29 -> -779.25 | F18: =-'Data Sheet'!F29 -> -748.71 | G18: =-'Data Sheet'!G29 -> -751.77 | H18: =-H17*H31 -> -904.50412 | I18: =-I17*I31 -> -984.39369 | J18: =-J17*J31 -> -1067.2531 | K18: =-K17*K31 -> -1153.1195 | L18: =-L17*L31 -> -1242.0132 | M18: =-M17*M31 -> -1333.9381 | N18: =-N17*N31 -> -1428.8829 | O18: =-O17*O31 -> -1526.8221 | ... Q18: =-Q17*Q31 -> -1731.5145
B19: Net Profit | C19: =SUM(C17:C18) -> 1515.98 | D19: =SUM(D17:D18) -> 2316.32 | E19: =SUM(E17:E18) -> 2134.22 | F19: =SUM(F17:F18) -> 2177.86 | G19: =SUM(G17:G18) -> 2537.01 | H19: =SUM(H17:H18) -> 2688.5143 | I19: =SUM(I17:I18) -> 2925.975 | J19: =SUM(J17:J18) -> 3172.2632 | ... Q19: =SUM(Q17:Q18) -> 5146.6891
A21: # | B21: Ratios & Assumptions
B23: Scenario | C23: Base Case | D23: =IF(C23=B123,1,IF(C23=B124,2,3)) -> 1
B24: Revenue Growth | C24: N/A | D24: =D7/C7-1 -> 0.15310202 | E24: =E7/D7-1 -> 0.028754858 | F24: =F7/E7-1 -> 0.069973231 | G24: =G7/F7-1 -> 0.067376817 | H24: =CHOOSE($D$23,H123:Q123,H124:Q124,H125:Q125) -> 0.079801732 | I24: =CHOOSE($D$23,I123:R123,I124:R124,I125:R125) -> 0.07740768 | J24: =CHOOSE($D$23,J123:S123,J124:S124,J125:S125) -> 0.07508545 | K24: =CHOOSE($D$23,K123:T123,K124:T124,K125:T125) -> 0.072832886 | L24: =CHOOSE($D$23,L123:U123,L124:U124,L125:U125) -> 0.0706479 | M24: =CHOOSE($D$23,M123:V123,M124:V124,M125:V125) -> 0.068528463 | N24: =CHOOSE($D$23,N123:W123,N124:W124,N125:W125) -> 0.066472609 | O24: =CHOOSE($D$23,O123:X123,O124:X124,O125:X125) -> 0.064478431 | ... Q24: =CHOOSE($D$23,Q123:Z123,Q124:Z124,Q125:Z125) -> 0.060667755
B25: COGS as % of Sales | C25: =-C8/C7 -> 0.61970422 | D25: =-D8/D7 -> 0.58840346 | E25: =-E8/E7 -> 0.56603716 | F25: =-F8/F7 -> 0.59099621 | G25: =-G8/G7 -> 0.58130317 | H25: =AVERAGE(C25:G25) -> 0.58928885 | I25: =H25 -> 0.58928885 | J25: =I25 -> 0.58928885 | K25: =J25 -> 0.58928885 | L25: =K25 -> 0.58928885 | M25: =L25 -> 0.58928885 | N25: =M25 -> 0.58928885 | O25: =N25 -> 0.58928885 | P25: =O25 -> 0.58928885 | Q25: =P25 -> 0.58928885
B26: Salaries & benefits as % of Revenue | C26: =-C10/C7 -> 0.03835951 | D26: =-D10/D7 -> 0.040390048 | E26: =-E10/E7 -> 0.042261828 | F26: =-F10/F7 -> 0.039268961 | G26: =-G10/G7 -> 0.043014705 | H26: =AVERAGE(C26:G26) -> 0.04065901 | I26: =H26 -> 0.04065901 | J26: =I26 -> 0.04065901 | K26: =J26 -> 0.04065901 | L26: =K26 -> 0.04065901 | M26: =L26 -> 0.04065901 | N26: =M26 -> 0.04065901 | O26: =N26 -> 0.04065901 | P26: =O26 -> 0.04065901 | Q26: =P26 -> 0.04065901
B27: Other SG&A Expenses as % of Revenue | C27: =-C11/C7 -> 0.1862013 | D27: =-D11/D7 -> 0.19753689 | E27: =-E11/E7 -> 0.2026743 | F27: =-F11/F7 -> 0.19210519 | G27: =-G11/G7 -> 0.19060976 | H27: =AVERAGE(C27:G27) -> 0.19382549 | I27: =H27 -> 0.19382549 | J27: =I27 -> 0.19382549 | K27: =J27 -> 0.19382549 | L27: =K27 -> 0.19382549 | M27: =L27 -> 0.19382549 | N27: =M27 -> 0.19382549 | O27: =N27 -> 0.19382549 | P27: =O27 -> 0.19382549 | Q27: =P27 -> 0.19382549
B28: D&A as % of opening PP&E | C28: NA | D28: =-D111/D109 -> 0.10587811 | E28: =-E111/E109 -> 0.11477489 | F28: =-F111/F109 -> 0.11119391 | G28: =-G111/G109 -> 0.11807369 | H28: =AVERAGE(D28:G28) -> 0.11248015 | I28: =H28 -> 0.11248015 | J28: =I28 -> 0.11248015 | K28: =J28 -> 0.11248015 | L28: =K28 -> 0.11248015 | M28: =L28 -> 0.11248015 | N28: =M28 -> 0.11248015 | O28: =N28 -> 0.11248015 | P28: =O28 -> 0.11248015 | Q28: =P28 -> 0.11248015
B29: Interest as % of opening debt | C29: NA | D29: =-D118/D115 -> 0.068152507 | E29: =-E118/E115 -> 0.054714633 | F29: =-F118/F115 -> 0.067216798 | G29: =-G118/G115 -> 0.090460566 | H29: =AVERAGE(D29:G29) -> 0.070136126 | I29: =H29 -> 0.070136126 | J29: =I29 -> 0.070136126 | K29: =J29 -> 0.070136126 | L29: =K29 -> 0.070136126 | M29: =L29 -> 0.070136126 | N29: =M29 -> 0.070136126 | O29: =N29 -> 0.070136126 | P29: =O29 -> 0.070136126 | Q29: =P29 -> 0.070136126
B30: Other Income (Expense) as % of Revenue | C30: =C16/C7 -> 0.015679536 | D30: =D16/D7 -> 0.036616556 | E30: =E16/E7 -> 0.012409008 | F30: =F16/F7 -> 0.010676226 | G30: =G16/G7 -> 0.010126574 | H30: =AVERAGE(C30:G30) -> 0.01710158 | I30: =H30 -> 0.01710158 | J30: =I30 -> 0.01710158 | K30: =J30 -> 0.01710158 | L30: =K30 -> 0.01710158 | M30: =L30 -> 0.01710158 | N30: =M30 -> 0.01710158 | O30: =N30 -> 0.01710158 | P30: =O30 -> 0.01710158 | Q30: =P30 -> 0.01710158
B31: Taxes Rate | C31: =-C18/C17 -> 0.27057782 | D31: =-D18/D17 -> 0.23623618 | E31: =-E18/E17 -> 0.26746457 | F31: =-F18/F17 -> 0.25583191 | G31: =-G18/G17 -> 0.22858628 | H31: =AVERAGE(C31:G31) -> 0.25173935 | I31: =H31 -> 0.25173935 | J31: =I31 -> 0.25173935 | K31: =J31 -> 0.25173935 | L31: =K31 -> 0.25173935 | M31: =L31 -> 0.25173935 | N31: =M31 -> 0.25173935 | O31: =N31 -> 0.25173935 | P31: =O31 -> 0.25173935 | Q31: =P31 -> 0.25173935
B32: Dividend payout ratio | C32: =-C91/C19 -> 1.6391245 | D32: =-D91/D19 -> 0.58681011 | E32: =-E91/E19 -> 0.81175793 | F32: =-F91/F19 -> 0.81159487 | G32: =-G91/G19 -> 0.71105356 | H32: =AVERAGE(C32:G32) -> 0.9120682 | I32: =H32 -> 0.9120682 | J32: =I32 -> 0.9120682 | K32: =J32 -> 0.9120682 | L32: =K32 -> 0.9120682 | M32: =L32 -> 0.9120682 | N32: =M32 -> 0.9120682 | O32: =N32 -> 0.9120682 | P32: =O32 -> 0.9120682 | Q32: =P32 -> 0.9120682
B33: DSO | C33: =C43/C7*365 -> 8.5704741 | D33: =D43/D7*365 -> 7.3655858 | E33: =E43/E7*365 -> 8.5612224 | F33: =F43/F7*365 -> 9.1258798 | G33: =G43/G7*365 -> 8.9424246 | H33: =AVERAGE(C33:G33) -> 8.5131174 | I33: =H33 -> 8.5131174 | J33: =I33 -> 8.5131174 | K33: =J33 -> 8.5131174 | L33: =K33 -> 8.5131174 | M33: =L33 -> 8.5131174 | N33: =M33 -> 8.5131174 | O33: =N33 -> 8.5131174 | P33: =O33 -> 8.5131174 | Q33: =P33 -> 8.5131174
B34: DIO | C34: =-C44/C8*365 -> 56.976799 | D34: =-D44/D8*365 -> 45.409892 | E34: =-E44/E8*365 -> 45.421822 | F34: =-F44/F8*365 -> 42.561677 | G34: =-G44/G8*365 -> 44.127346 | H34: =AVERAGE(C34:G34) -> 46.899507 | I34: =H34 -> 46.899507 | J34: =I34 -> 46.899507 | K34: =J34 -> 46.899507 | L34: =K34 -> 46.899507 | M34: =L34 -> 46.899507 | N34: =M34 -> 46.899507 | O34: =N34 -> 46.899507 | P34: =O34 -> 46.899507 | Q34: =P34 -> 46.899507
B35: DPO | C35: =-C56/C8*365 -> 55.115196 | D35: =-D56/D8*365 -> 55.13493 | E35: =-E56/E8*365 -> 62.581998 | F35: =-F56/F8*365 -> 60.313178 | G35: =-G56/G8*365 -> 62.175255 | H35: =AVERAGE(C35:G35) -> 59.064111 | I35: =H35 -> 59.064111 | J35: =I35 -> 59.064111 | K35: =J35 -> 59.064111 | L35: =K35 -> 59.064111 | M35: =L35 -> 59.064111 | N35: =M35 -> 59.064111 | O35: =N35 -> 59.064111 | P35: =O35 -> 59.064111 | Q35: =P35 -> 59.064111
B36: Capital Asset Turnover Ratio | C36: =C7/C48 -> 6.6252953 | D36: =D7/D48 -> 6.226765 | E36: =E7/E48 -> 5.9508545 | F36: =F7/F48 -> 6.289693 | G36: =G7/G48 -> 6.9898355 | H36: =AVERAGE(C36:G36) -> 6.4164886 | I36: =H36 -> 6.4164886 | J36: =I36 -> 6.4164886 | K36: =J36 -> 6.4164886 | L36: =K36 -> 6.4164886 | M36: =L36 -> 6.4164886 | N36: =M36 -> 6.4164886 | O36: =N36 -> 6.4164886 | P36: =O36 -> 6.4164886 | Q36: =P36 -> 6.4164886
A38: # | B38: Balance Sheet
B40: Current Assets
B41: Cash | C41: ='Data Sheet'!C62 -> 117.99 | D41: ='Data Sheet'!D62 -> 102.38 | E41: ='Data Sheet'!E62 -> 322.8 | F41: ='Data Sheet'!F62 -> 132.78 | G41: ='Data Sheet'!G62 -> 220 | H41: =H97 -> 368.95022 | I41: =I97 -> 671.17252 | J41: =J97 -> 977.81984 | K41: =K97 -> 1291.6685 | L41: =L97 -> 1615.3129 | M41: =M97 -> 1951.1813 | N41: =N97 -> 2301.55 | O41: =O97 -> 2668.555 | ... Q41: =Q97 -> 3460.375
B42: Bank Deposits | C42: ='Data Sheet'!C63 -> 66.91 | D42: ='Data Sheet'!D63 -> 95.6 | E42: ='Data Sheet'!E63 -> 123.55 | F42: ='Data Sheet'!F63 -> 179.7 | G42: ='Data Sheet'!G63 -> 132.44 | H42: =G42 -> 132.44 | I42: =H42 -> 132.44 | J42: =I42 -> 132.44 | K42: =J42 -> 132.44 | L42: =K42 -> 132.44 | M42: =L42 -> 132.44 | N42: =M42 -> 132.44 | O42: =N42 -> 132.44 | ... Q42: =P42 -> 132.44
B43: Account Receivable | C43: ='Data Sheet'!C61 -> 331.93 | D43: ='Data Sheet'!D61 -> 328.94 | E43: ='Data Sheet'!E61 -> 393.33 | F43: ='Data Sheet'!F61 -> 448.61 | G43: ='Data Sheet'!G61 -> 469.21 | H43: =H7*H33/365 -> 482.33037 | I43: =I7*I33/365 -> 519.66645 | J43: =J7*J33/365 -> 558.68584 | K43: =K7*K33/365 -> 599.37654 | L43: =L7*L33/365 -> 641.72123 | M43: =M7*M33/365 -> 685.6974 | N43: =N7*N33/365 -> 731.2775 | O43: =O7*O33/365 -> 778.42912 | ... Q43: =Q7*Q33/365 -> 877.29448
B44: Inventory | C44: ='Data Sheet'!C58 -> 1367.49 | D44: ='Data Sheet'!D58 -> 1193.26 | E44: ='Data Sheet'!E58 -> 1181.22 | F44: ='Data Sheet'!F58 -> 1236.51 | G44: ='Data Sheet'!G58 -> 1345.93 | H44: =-H8*H34/365 -> 1565.8584 | I44: =-I8*I34/365 -> 1687.0679 | J44: =-J8*J34/365 -> 1813.7421 | K44: =-K8*K34/365 -> 1945.8422 | L44: =-L8*L34/365 -> 2083.3119 | M44: =-M8*M34/365 -> 2226.078 | N44: =-N8*N34/365 -> 2374.0513 | O44: =-O8*O34/365 -> 2527.1264 | ... Q44: =-Q8*Q34/365 -> 2848.0872
B45: Other current assets | C45: ='Data Sheet'!C66 -> 138.22 | D45: ='Data Sheet'!D66 -> 180.74 | E45: ='Data Sheet'!E66 -> 133.71 | F45: ='Data Sheet'!F66 -> 123.98 | G45: ='Data Sheet'!G66 -> 142.03 | H45: =G45 -> 142.03 | I45: =H45 -> 142.03 | J45: =I45 -> 142.03 | K45: =J45 -> 142.03 | L45: =K45 -> 142.03 | M45: =L45 -> 142.03 | N45: =M45 -> 142.03 | O45: =N45 -> 142.03 | ... Q45: =P45 -> 142.03
B47: Non Current Assets
...

Sheet Comps Data
B2: S.No. | C2: Company | D2: CMP Rs. | E2: No. Eq. Shares Cr. | F2: Debt Rs.Cr. | G2: Cash Rs.Cr. | H2: Sales Rs.Cr. | I2: EV / EBITDA | J2: Tax 12M Rs.Cr. | K2: Current Tax 12M Rs.Cr. | L2: Mar Cap Rs.Cr. | M2: EV Rs.Cr. | N2: NP Ann Rs.Cr. | O2: Tax Rate
B3: 1 | C3: Nestle India | D3: 1362.6 | E3: 192.83 | F3: 444.16 | G3: 1340.87 | H3: 24436.62 | I3: 45.13 | J3: 1173.08 | K3: 1152.89 | L3: 262752.11 | M3: 261855.4 | N3: 3544.6 | O3: 0.235357
B4: 2 | C4: Britannia Industries Limited | D4: 4937.5 | E4: 24.09 | F4: 1380.28 | G4: 352.44 | H4: 19529.34 | I4: 31.33 | J4: 774.85 | K4: 781.69 | L4: 118928.72 | M4: 119956.56 | N4: 2537.01 | O4: 0.228899
B5: 3 | C5: Gopal Snacks | D5: 251.65 | E5: 12.47 | F5: 154.03 | G5: 0.75 | H5: 1608.37 | I5: 26.9 | J5: 28.58 | K5: 24.1 | L5: 3137.24 | M5: 3290.52 | N5: 73.65 | O5: 0.253898
B6: 4 | C6: Bikiaji Foods | D6: 573.95 | E6: 25.07 | F6: 216.92 | G6: 247.68 | H6: 2871.7 | I6: 31.24 | J6: 93.46 | K6: 95.4 | L6: 14391.02 | M6: 14360.26 | N6: 269.07 | O6: 0.263964
B7: 5 | C7: The Bombay Burmah | D7: 1435.2 | E7: 6.98 | F7: 1590.43 | G7: 842.81 | H7: 19915.4 | I7: 2.81 | J7: 875.28 | K7: 882.12 | L7: 10013.66 | M7: 10761.28 | N7: 2499.25 | O7: 0.253004
B8: 6 | C8: Mrs Bectors | D8: 215.58 | E8: 30.7 | F8: 170.6 | G8: 191.63 | H8: 1968.09 | I8: 24.45 | J8: 42.79 | K8: 41.01 | L8: 6618.1 | M8: 6597.07 | N8: 118.78 | O8: 0.248904

Sheet Ratio Analysis
B2: ='Data Sheet'!B2 -> Britannia Industries Ltd
B3: Ratio Analysis | C3: 2022 | D3: =C3+1 -> 2023 | E3: =D3+1 -> 2024 | F3: =E3+1 -> 2025 | G3: =F3+1 -> 2026 | H3: =G3+1 -> 2027 | I3: =H3+1 -> 2028 | J3: =I3+1 -> 2029 | K3: =J3+1 -> 2030 | ... Q3: =P3+1 -> 2036
B5: Profitability Ratios
B6: Gross Margin | C6: =Model!C9/Model!C7 -> 0.38029578 | D6: =Model!D9/Model!D7 -> 0.41159654 | E6: =Model!E9/Model!E7 -> 0.43396284 | F6: =Model!F9/Model!F7 -> 0.40900379 | G6: =Model!G9/Model!G7 -> 0.41869683 | H6: =Model!H9/Model!H7 -> 0.41071115 | I6: =Model!I9/Model!I7 -> 0.41071115 | J6: =Model!J9/Model!J7 -> 0.41071115 | ... Q6: =Model!Q9/Model!Q7 -> 0.41071115
B7: EBITDA Margin | C7: =Model!C12/Model!C7 -> 0.15573497 | D7: =Model!D12/Model!D7 -> 0.1736696 | E7: =Model!E12/Model!E7 -> 0.18902671 | F7: =Model!F12/Model!F7 -> 0.17762964 | G7: =Model!G12/Model!G7 -> 0.18507236 | H7: =Model!H12/Model!H7 -> 0.17622666 | I7: =Model!I12/Model!I7 -> 0.17622666 | J7: =Model!J12/Model!J7 -> 0.17622666 | ... Q7: =Model!Q12/Model!Q7 -> 0.17622666
B8: EBIT Margin | C8: =Model!C14/Model!C7 -> 0.14154875 | D8: =Model!D14/Model!D7 -> 0.15981056 | E8: =Model!E14/Model!E7 -> 0.17110942 | F8: =Model!F14/Model!F7 -> 0.16016624 | G8: =Model!G14/Model!G7 -> 0.16748479 | H8: =Model!H14/Model!H7 -> 0.16132396 | I8: =Model!I14/Model!I7 -> 0.16274804 | J8: =Model!J14/Model!J7 -> 0.1639281 | ... Q8: =Model!Q14/Model!Q7 -> 0.16833494
B9: Pre Tax Margin | C9: =Model!C17/Model!C7 -> 0.14702121 | D9: =Model!D17/Model!D7 -> 0.18605323 | E9: =Model!E17/Model!E7 -> 0.17373863 | F9: =Model!F17/Model!F7 -> 0.16310672 | G9: =Model!G17/Model!G7 -> 0.1717236 | H9: =Model!H17/Model!H7 -> 0.17374431 | I9: =Model!I17/Model!I7 -> 0.17550471 | J9: =Model!J17/Model!J7 -> 0.17698823 | ... Q9: =Model!Q17/Model!Q7 -> 0.18286281
B10: Effective Tax Rate | C10: =Model!C31 -> 0.27057782 | D10: =Model!D31 -> 0.23623618 | E10: =Model!E31 -> 0.26746457 | F10: =Model!F31 -> 0.25583191 | G10: =Model!G31 -> 0.22858628 | H10: =Model!H31 -> 0.25173935 | I10: =Model!I31 -> 0.25173935 | J10: =Model!J31 -> 0.25173935 | ... Q10: =Model!Q31 -> 0.25173935
B11: ROIC | C11: =Model!C14*(1-Model!C31)/(Model!C67+Model!C60-Model!C41-Model!C42) -> 0.30066577 | D11: =Model!D14*(1-Model!D31)/(Model!D67+Model!D60-Model!D41-Model!D42) -> 0.31413192 | E11: =Model!E14*(1-Model!E31)/(Model!E67+Model!E60-Model!E41-Model!E42) -> 0.37803478 | F11: =Model!F14*(1-Model!F31)/(Model!F67+Model!F60-Model!F41-Model!F42) -> 0.40429088 | G11: =Model!G14*(1-Model!G31)/(Model!G67+Model!G60-Model!G41-Model!G42) -> 0.40336245 | H11: =Model!H14*(1-Model!H31)/(Model!H67+Model!H60-Model!H41-Model!H42) -> 0.40121827 | I11: =Model!I14*(1-Model!I31)/(Model!I67+Model!I60-Model!I41-Model!I42) -> 0.43926402 | J11: =Model!J14*(1-Model!J31)/(Model!J67+Model!J60-Model!J41-Model!J42) -> 0.47781363 | ... Q11: =Model!Q14*(1-Model!Q31)/(Model!Q67+Model!Q60-Model!Q41-Model!Q42) -> 0.75301037
B12: Net Margin | C12: =Model!C19/Model!C7 -> 0.10724053 | D12: =Model!D19/Model!D7 -> 0.14210073 | E12: =Model!E19/Model!E7 -> 0.1272697 | F12: =Model!F19/Model!F7 -> 0.12137881 | G12: =Model!G19/Model!G7 -> 0.13246994 | H12: =Model!H19/Model!H7 -> 0.13000603 | I12: =Model!I19/Model!I7 -> 0.13132327 | J12: =Model!J19/Model!J7 -> 0.13243333 | ... Q12: =Model!Q19/Model!Q7 -> 0.13682905
B14: Dupont / Earning Power
B15: Asset Turnover | D15: =Model!D7/AVERAGE(Model!C53:D53) -> 1.9313299 | E15: =Model!E7/AVERAGE(Model!D53:E53) -> 1.8201471 | F15: =Model!F7/AVERAGE(Model!E53:F53) -> 2.0034122 | G15: =Model!G7/AVERAGE(Model!F53:G53) -> 2.0625832 | H15: =Model!H7/AVERAGE(Model!G53:H53) -> 2.0914285 | I15: =Model!I7/AVERAGE(Model!H53:I53) -> 2.173959 | J15: =Model!J7/AVERAGE(Model!I53:J53) -> 2.2442997 | K15: =Model!K7/AVERAGE(Model!J53:K53) -> 2.3097035 | ... Q15: =Model!Q7/AVERAGE(Model!P53:Q53) -> 2.5956318
B16: Pretax ROA | D16: =Model!D17/AVERAGE(Model!C53:D53) -> 0.35933017 | E16: =Model!E17/AVERAGE(Model!D53:E53) -> 0.31622986 | F16: =Model!F17/AVERAGE(Model!E53:F53) -> 0.32676999 | G16: =Model!G17/AVERAGE(Model!F53:G53) -> 0.35419421 | H16: =Model!H17/AVERAGE(Model!G53:H53) -> 0.3633738 | I16: =Model!I17/AVERAGE(Model!H53:I53) -> 0.38154005 | J16: =Model!J17/AVERAGE(Model!I53:J53) -> 0.39721465 | K16: =Model!K17/AVERAGE(Model!J53:K53) -> 0.41169488 | ... Q16: =Model!Q17/AVERAGE(Model!P53:Q53) -> 0.47464452
B17: Pretax ROE | D17: =Model!D17/AVERAGE(Model!C67:D67) -> 0.99559613 | E17: =Model!E17/AVERAGE(Model!D67:E67) -> 0.77944137 | F17: =Model!F17/AVERAGE(Model!E67:F67) -> 0.70543217 | G17: =Model!G17/AVERAGE(Model!F67:G67) -> 0.69513479 | H17: =Model!H17/AVERAGE(Model!G67:H67) -> 0.68769022 | I17: =Model!I17/AVERAGE(Model!H67:I67) -> 0.71466523 | J17: =Model!J17/AVERAGE(Model!I67:J67) -> 0.73862725 | K17: =Model!K17/AVERAGE(Model!J67:K67) -> 0.75965079 | ... Q17: =Model!Q17/AVERAGE(Model!P67:Q67) -> 0.83089461
B18: Tax Complement | C18: =Model!C19/Model!C17 -> 0.72942218 | D18: =Model!D19/Model!D17 -> 0.76376382 | E18: =Model!E19/Model!E17 -> 0.73253543 | F18: =Model!F19/Model!F17 -> 0.74416809 | G18: =Model!G19/Model!G17 -> 0.77141372 | H18: =Model!H19/Model!H17 -> 0.74826065 | I18: =Model!I19/Model!I17 -> 0.74826065 | J18: =Model!J19/Model!J17 -> 0.74826065 | ... Q18: =Model!Q19/Model!Q17 -> 0.74826065
B19: ROE | D19: =Model!D19/AVERAGE(Model!C67:D67) -> 0.7604003 | E19: =Model!E19/AVERAGE(Model!D67:E67) -> 0.57096842 | F19: =Model!F19/AVERAGE(Model!E67:F67) -> 0.52496011 | G19: =Model!G19/AVERAGE(Model!F67:G67) -> 0.53623651 | H19: =Model!H19/AVERAGE(Model!G67:H67) -> 0.51457153 | I19: =Model!I19/AVERAGE(Model!H67:I67) -> 0.53475587 | J19: =Model!J19/AVERAGE(Model!I67:J67) -> 0.5526857 | K19: =Model!K19/AVERAGE(Model!J67:K67) -> 0.56841679 | ... Q19: =Model!Q19/AVERAGE(Model!P67:Q67) -> 0.62172574
B20: Reinvestment Rate | D20: =(Model!D110+Model!D111-Model!D106)/(Model!D14*(1-Model!D31)) -> 0.03944502 | E20: =(Model!E110+Model!E111-Model!E106)/(Model!E14*(1-Model!E31)) -> 0.018573473 | F20: =(Model!F110+Model!F111-Model!F106)/(Model!F14*(1-Model!F31)) -> 0.013550936 | G20: =(Model!G110+Model!G111-Model!G106)/(Model!G14*(1-Model!G31)) -> 0.0034149877 | H20: =(Model!H110+Model!H111-Model!H106)/(Model!H14*(1-Model!H31)) -> 0.03503381 | I20: =(Model!I110+Model!I111-Model!I106)/(Model!I14*(1-Model!I31)) -> -0.016561407 | J20: =(Model!J110+Model!J111-Model!J106)/(Model!J14*(1-Model!J31)) -> -0.0094291445 | K20: =(Model!K110+Model!K111-Model!K106)/(Model!K14*(1-Model!K31)) -> -0.0039303222 | ... Q20: =(Model!Q110+Model!Q111-Model!Q106)/(Model!Q14*(1-Model!Q31)) -> 0.0097903105
B22: Liquidity Ratio
B23: Current Ratio | C23: =SUM(Model!C41:C45)/SUM(Model!C56:C57) -> 0.84742468 | D23: =SUM(Model!D41:D45)/SUM(Model!D56:D57) -> 0.70321361 | E23: =SUM(Model!E41:E45)/SUM(Model!E56:E57) -> 0.73179024 | F23: =SUM(Model!F41:F45)/SUM(Model!F56:F57) -> 0.68346788 | G23: =SUM(Model!G41:G45)/SUM(Model!G56:G57) -> 0.74380461 | H23: =SUM(Model!H41:H45)/SUM(Model!H56:H57) -> 0.84622516 | I23: =SUM(Model!I41:I45)/SUM(Model!I56:I57) -> 0.94570189 | J23: =SUM(Model!J41:J45)/SUM(Model!J56:J57) -> 1.0377378 | ... Q23: =SUM(Model!Q41:Q45)/SUM(Model!Q56:Q57) -> 1.5556618
B24: Quick Ratio | C24: =SUM(Model!C41:C43)/SUM(Model!C56:C57) -> 0.21654677 | D24: =SUM(Model!D41:D43)/SUM(Model!D56:D57) -> 0.19492525 | E24: =SUM(Model!E41:E43)/SUM(Model!E56:E57) -> 0.28518833 | F24: =SUM(Model!F41:F43)/SUM(Model!F56:F57) -> 0.24518546 | G24: =SUM(Model!G41:G43)/SUM(Model!G56:G57) -> 0.2646105 | H24: =SUM(Model!H41:H43)/SUM(Model!H56:H57) -> 0.30927565 | I24: =SUM(Model!I41:I43)/SUM(Model!I56:I57) -> 0.396979 | J24: =SUM(Model!J41:J43)/SUM(Model!J56:J57) -> 0.47781046 | ... Q24: =SUM(Model!Q41:Q43)/SUM(Model!Q56:Q57) -> 0.93214039
B25: Cash Ratio | C25: =SUM(Model!C41:C42)/SUM(Model!C56:C57) -> 0.07747131 | D25: =SUM(Model!D41:D42)/SUM(Model!D56:D57) -> 0.073239395 | E25: =SUM(Model!E41:E42)/SUM(Model!E56:E57) -> 0.151598 | F25: =SUM(Model!F41:F42)/SUM(Model!F56:F57) -> 0.10066556 | G25: =SUM(Model!G41:G42)/SUM(Model!G56:G57) -> 0.11350249 | H25: =SUM(Model!H41:H42)/SUM(Model!H56:H57) -> 0.15763397 | I25: =SUM(Model!I41:I42)/SUM(Model!I56:I57) -> 0.24108091 | J25: =SUM(Model!J41:J42)/SUM(Model!J56:J57) -> 0.31786161 | ... Q25: =SUM(Model!Q41:Q42)/SUM(Model!Q56:Q57) -> 0.74920044
B26: Cash Conversion Cycle | D26: =D35+D37-D39 -> 3.3866989 | E26: =E35+E37-E39 -> -5.6329939 | F26: =F35+F37-F39 -> -7.9924546 | G26: =G35+G37-G39 -> -8.7319695 | H26: =H35+H37-H39 -> -5.9287696 | I26: =I35+I37-I39 -> -3.5203137 | J26: =J35+J37-J39 -> -3.523974 | K26: =K35+K37-K39 -> -3.5275397 | ... Q26: =Q35+Q37-Q39 -> -3.5470581
B28: Solvency Ratios
B29: Asset / Equity | C29: =Model!C53/Model!C67 -> 2.9425785 | D29: =Model!D53/Model!D67 -> 2.6462947 | E29: =Model!E53/Model!E67 -> 2.3020459 | F29: =Model!F53/Model!F67 -> 2.0291823 | G29: =Model!G53/Model!G67 -> 1.9057722 | H29: =Model!H53/Model!H67 -> 1.8798436 | I29: =Model!I53/Model!I67 -> 1.8666793 | J29: =Model!J53/Model!J67 -> 1.8526938 | ... Q29: =Model!Q53/Model!Q67 -> 1.7426533
B30: Debt / Equity | C30: =Model!C60/Model!C67 -> 0.96993863 | D30: =Model!D60/Model!D67 -> 0.84808744 | E30: =Model!E60/Model!E67 -> 0.52389941 | F30: =Model!F60/Model!F67 -> 0.28617772 | G30: =Model!G60/Model!G67 -> 0.27029546 | H30: =Model!H60/Model!H67 -> 0.25833592 | I30: =Model!I60/Model!I67 -> 0.24646747 | J30: =Model!J60/Model!J67 -> 0.23477364 | ... Q30: =Model!Q60/Model!Q67 -> 0.16230284
B31: Debt / Total Capital | C31: =Model!C60/SUM(Model!C60,Model!C67) -> 0.49236997 | D31: =Model!D60/SUM(Model!D60,Model!D67) -> 0.45890006 | E31: =Model!E60/SUM(Model!E60,Model!E67) -> 0.34378871 | F31: =Model!F60/SUM(Model!F60,Model!F67) -> 0.22250247 | G31: =Model!G60/SUM(Model!G60,Model!G67) -> 0.21278157 | H31: =Model!H60/SUM(Model!H60,Model!H67) -> 0.20529965 | I31: =Model!I60/SUM(Model!I60,Model!I67) -> 0.19773278 | J31: =Model!J60/SUM(Model!J60,Model!J67) -> 0.19013496 | ... Q31: =Model!Q60/SUM(Model!Q60,Model!Q67) -> 0.13963903
B33: Activity Ratios (Efficiency)
B34: Debtor Turnover Ratio | D34: =Model!D7/AVERAGE(Model!C43:D43) -> 49.330579 | E34: =Model!E7/AVERAGE(Model!D43:E43) -> 46.434907 | F34: =Model!F7/AVERAGE(Model!E43:F43) -> 42.622206 | G34: =Model!G7/AVERAGE(Model!F43:G43) -> 41.73278 | H34: =Model!H7/AVERAGE(Model!G43:H43) -> 43.466196 | I34: =Model!I7/AVERAGE(Model!H43:I43) -> 44.472606 | J34: =Model!J7/AVERAGE(Model!I43:J43) -> 44.426412 | K34: =Model!K7/AVERAGE(Model!J43:K43) -> 44.381505 | ... Q34: =Model!Q7/AVERAGE(Model!P43:Q43) -> 44.137287
B35: DSO | D35: =365/D34 -> 7.3990617 | E35: =365/E34 -> 7.8604659 | F35: =365/F34 -> 8.5636112 | G35: =365/G34 -> 8.7461224 | H35: =365/H34 -> 8.3973302 | I35: =365/I34 -> 8.2072997 | J35: =365/J34 -> 8.2158334 | K35: =365/K34 -> 8.2241465 | ... Q35: =365/Q34 -> 8.269652
B36: Inventory Turnover Ratio | D36: =-Model!D8/AVERAGE(Model!C44:D44) -> 7.4910085 | E36: =-Model!E8/AVERAGE(Model!D44:E44) -> 7.9950389 | F36: =-Model!F8/AVERAGE(Model!E44:F44) -> 8.7719059 | G36: =-Model!G8/AVERAGE(Model!F44:G44) -> 8.6219854 | H36: =-Model!H8/AVERAGE(Model!G44:H44) -> 8.3704201 | I36: =-Model!I8/AVERAGE(Model!H44:I44) -> 8.0725903 | J36: =-Model!J8/AVERAGE(Model!I44:J44) -> 8.0642054 | K36: =-Model!K8/AVERAGE(Model!J44:K44) -> 8.056054 | ... Q36: =-Model!Q8/AVERAGE(Model!P44:Q44) -> 8.0117238
B37: DSI | D37: =365/D36 -> 48.725082 | E37: =365/E36 -> 45.653311 | F37: =365/F36 -> 41.610114 | G37: =365/G36 -> 42.333637 | H37: =365/H36 -> 43.605935 | I37: =365/I36 -> 45.214731 | J37: =365/J36 -> 45.261744 | K37: =365/K36 -> 45.307542 | ... Q37: =365/Q36 -> 45.558235
B38: Payble Turnover Ratio | D38: =-Model!D8/AVERAGE(Model!C56:D56) -> 6.9210786 | E38: =-Model!E8/AVERAGE(Model!D56:E56) -> 6.1710892 | F38: =-Model!F8/AVERAGE(Model!E56:F56) -> 6.2751242 | G38: =-Model!G8/AVERAGE(Model!F56:G56) -> 6.102482 | H38: =-Model!H8/AVERAGE(Model!G56:H56) -> 6.3004864 | I38: =-Model!I8/AVERAGE(Model!H56:I56) -> 6.4099925 | J38: =-Model!J8/AVERAGE(Model!I56:J56) -> 6.4033345 | K38: =-Model!K8/AVERAGE(Model!J56:K56) -> 6.3968619 | ... Q38: =-Model!Q8/AVERAGE(Model!P56:Q56) -> 6.3616618
B39: DPO | D39: =365/D38 -> 52.737444 | E39: =365/E38 -> 59.146771 | F39: =365/F38 -> 58.166179 | G39: =365/G38 -> 59.811729 | H39: =365/H38 -> 57.932035 | I39: =365/I38 -> 56.942344 | J39: =365/J38 -> 57.001552 | K39: =365/K38 -> 57.059228 | ... Q39: =365/Q38 -> 57.374945
B40: Fixed Asset Turnover | D40: =Model!D7/AVERAGE(Model!C48:D48) -> 6.8612228 | E40: =Model!E7/AVERAGE(Model!D48:E48) -> 6.169959 | F40: =Model!F7/AVERAGE(Model!E48:F48) -> 6.3282363 | G40: =Model!G7/AVERAGE(Model!F48:G48) -> 6.8488672 | H40: =Model!H7/AVERAGE(Model!G48:H48) -> 7.6452964 | I40: =Model!I7/AVERAGE(Model!H48:I48) -> 8.4252847 | J40: =Model!J7/AVERAGE(Model!I48:J48) -> 9.2053198 | K40: =Model!K7/AVERAGE(Model!J48:K48) -> 9.9769097 | ... Q40: =Model!Q7/AVERAGE(Model!P48:Q48) -> 14.149834

Sheet Market Return
B2: ='Ratio Analysis'!B2 -> Britannia Industries Ltd
B3: Equity Market Return
C5: Index
B6: Date | C6: Close Price
B7: 46290 | C7: 35161.85 | F7: Index | H7: Nifty 50 TRI
B8: 46289 | C8: 35044.24 | F8: No. of Years | H8: =YEARFRAC(B7,B2480) -> 9.9944444
B9: 46288 | C9: 35627.25 | F9: CAGR---> | H9: =(C7/C2480)^(1/H8)-1 -> 0.11613539
B10: 46287 | C10: 35448.24
B11: 46286 | C11: 35577.9
B12: 46283 | C12: 35474.68
B13: 46282 | C13: 35359.55
B14: 46281 | C14: 35279
B15: 46280 | C15: 35128.55
B16: 46276 | C16: 35553.3
B17: 46275 | C17: 35674.37
B18: 46274 | C18: 35604.02
B19: 46273 | C19: 35913.37
B20: 46272 | C20: 36132.24
B21: 46269 | C21: 36312.44
... B2480: 42640 | C2480: 11726.49

Sheet Beta & WACC 
B2: ='Ratio Analysis'!B2 -> Britannia Industries Ltd
B3: Weighted Average Cost of Capital (WACC)
B5: Comparable Companies Beta
D7: Equity | E7: Total | F7: Debt/ | G7: Debt/ | H7: Tax | I7: Levered | J7: Unlevered
B8: Company Name | D8: Value | E8: Debt | F8: Equity | G8: Capital | H8: Rate % | I8: Beta | J8: Beta
B9: Nestle India | D9: =Model!E137 -> 262750.16 | E9: =Model!F137 -> 444.16 | F9: =E9/D9 -> 0.0016904271 | G9: =E9/SUM(D9:E9) -> 0.0016875744 | H9: ='Comps Data'!O3 -> 0.235357 | I9: 0.42 | J9: =I9/(1+(1-H9)*F9) -> 0.41945782
B10: Gopal Snacks | D10: =Model!E138 -> 3138.0755 | E10: =Model!F138 -> 154.03 | F10: =E10/D10 -> 0.049084224 | G10: =E10/SUM(D10:E10) -> 0.046787686 | H10: ='Comps Data'!O5 -> 0.253898 | I10: 0.8 | J10: =I10/(1+(1-H10)*F10) -> 0.77173755
B11: Bikiaji Foods | D11: =Model!E139 -> 14388.927 | E11: =Model!F139 -> 216.92 | F11: =E11/D11 -> 0.015075482 | G11: =E11/SUM(D11:E11) -> 0.014851587 | H11: ='Comps Data'!O6 -> 0.263964 | I11: 0.23 | J11: =I11/(1+(1-H11)*F11) -> 0.22747591
B12: The Bombay Burmah | D12: =Model!E140 -> 10017.696 | E12: =Model!F140 -> 1590.43 | F12: =E12/D12 -> 0.15876205 | G12: =E12/SUM(D12:E12) -> 0.13701006 | H12: ='Comps Data'!O7 -> 0.253004 | I12: 0.61 | J12: =I12/(1+(1-H12)*F12) -> 0.54532714
B13: Mrs Bectors | D13: =Model!E141 -> 6618.306 | E13: =Model!F141 -> 170.6 | F13: =E13/D13 -> 0.025776989 | G13: =E13/SUM(D13:E13) -> 0.025129233 | H13: ='Comps Data'!O8 -> 0.248904 | I13: 0.17 | J13: =I13/(1+(1-H13)*F13) -> 0.16677114
B15: Average | F15: =AVERAGE(F9:F13) -> 0.050077835 | G15: =AVERAGE(G9:G13) -> 0.045093227 | H15: =AVERAGE(H9:H13) -> 0.2510254 | I15: =AVERAGE(I9:I13) -> 0.446 | J15: =AVERAGE(J9:J13) -> 0.42615391
B16: Median | F16: =MEDIAN(F9:F13) -> 0.025776989 | G16: =MEDIAN(G9:G13) -> 0.025129233 | H16: =MEDIAN(H9:H13) -> 0.253004 | I16: =MEDIAN(I9:I13) -> 0.42 | J16: =MEDIAN(J9:J13) -> 0.41945782
B18: Britannia Industries Limited | D18: =Model!E135 -> 118944.38 | E18: =Model!F135 -> 1380.28 | F18: =E18/D18 -> 0.011604416 | G18: =E18/SUM(D18:E18) -> 0.011471298 | H18: ='Comps Data'!O4 -> 0.228899 | I18: 0.41 | J18: =I18/(1+(1-H18)*F18) -> 0.40636379
A20: # | B20: WACC Calculation
B22: Target Capital Structure
B23: Proportion of Debt | D23: =G15 -> 0.045093227
B24: Proportion of Equity | D24: =1-D23 -> 0.95490677
B26: Current Capital Structure
B27: Market Cap. | D27: =D18 -> 118944.38
B28: Total Debt | D28: =E18 -> 1380.28
B29: Debt / Equity | D29: =D28/D27 -> 0.011604416
B31: Cost of Debt
B32: Pre Tax Cost of Debt | D32: =Model!H29 -> 0.070136126
B33: Tax Rate | D33: =H18 -> 0.228899
B34: After Tax Cost of Debt | D34: =D32*(1-D33) -> 0.054082037
B36: Cost of Equity
B37: Risk Free Rate | D37: 0.0712
B38: Equity Market Return | D38: ='Market Return'!H9 -> 0.11613539
B39: Equity Risk Premium | D39: =D38-D37 -> 0.044935386
B40: Levered Equity Beta | D40: =J16*(1+(1-H18)*D29) -> 0.4232112
B41: Cost of Equity | D41: =D37+D39*D40 -> 0.090217159
B43: WACC | D43: =D23*D34+D24*D41 -> 0.08858771

Sheet Beta from Regression
B2: ='Ratio Analysis'!B2 -> Britannia Industries Ltd
B3: Company Beta
C5: Index | D5: % Change | E5: Stock | F5: % Change | H5: Beta | I5: =SLOPE(F8:F67,D8:D67) -> -0.13364939
B6: Date | C6: Close Price | D6: Monthly | E6: Close Price | F6: Monthly
B7: 44440 | C7: 59126.36 | D7: NA | E7: 3982 | F7: NA
B8: 44470 | C8: 59306.93 | D8: =C8/C7-1 -> 0.0030539678 | E8: 3960 | F8: =E8/E7-1 -> -0.0055248619 | H8: SUMMARY OUTPUT
B9: 44501 | C9: 57064.87 | D9: =C9/C8-1 -> -0.037804351 | E9: 3675 | F9: =E9/E8-1 -> -0.071969697
B10: 44531 | C10: 58253.82 | D10: =C10/C9-1 -> 0.02083506 | E10: 3588 | F10: =E10/E9-1 -> -0.023673469 | H10: Regression Statistics
B11: 44562 | C11: 58014.17 | D11: =C11/C10-1 -> -0.0041138933 | E11: 3606.7 | F11: =E11/E10-1 -> 0.0052118172 | H11: Multiple R | I11: 0.080998582
B12: 44593 | C12: 56247.28 | D12: =C12/C11-1 -> -0.03045618 | E12: 3584.9 | F12: =E12/E11-1 -> -0.0060443064 | H12: R Square | I12: 0.0065607703
B13: 44621 | C13: 58568.51 | D13: =C13/C12-1 -> 0.041268307 | E13: 3406 | F13: =E13/E12-1 -> -0.049903763 | H13: Adjusted R Square | I13: -0.010567492
B14: 44652 | C14: 57060.87 | D14: =C14/C13-1 -> -0.025741478 | E14: 3193 | F14: =E14/E13-1 -> -0.0625367 | H14: Standard Error | I14: 0.062428226
B15: 44682 | C15: 55566.41 | D15: =C15/C14-1 -> -0.026190628 | E15: 3244 | F15: =E15/E14-1 -> 0.01597244 | H15: Observations | I15: 60
B16: 44713 | C16: 53018.94 | D16: =C16/C15-1 -> -0.045845503 | E16: 3656.2 | F16: =E16/E15-1 -> 0.12706535
B17: 44743 | C17: 57570.25 | D17: =C17/C16-1 -> 0.085843097 | E17: 3435 | F17: =E17/E16-1 -> -0.060499973 | H17: ANOVA
B18: 44774 | C18: 59537.07 | D18: =C18/C17-1 -> 0.034163826 | E18: 3900.85 | F18: =E18/E17-1 -> 0.13561863 | I18: df | J18: SS | K18: MS | L18: F | M18: Significance F
B19: 44805 | C19: 57426.92 | D19: =C19/C18-1 -> -0.035442624 | E19: 3743.6 | F19: =E19/E18-1 -> -0.040311727 | H19: Regression | I19: 1 | J19: 0.0014928065 | K19: 0.0014928065 | L19: 0.3830377 | M19: 0.53840531
B20: 44835 | C20: 60746.59 | D20: =C20/C19-1 -> 0.057806861 | E20: 3843.05 | F20: =E20/E19-1 -> 0.026565338 | H20: Residual | I20: 58 | J20: 0.22604244 | K20: 0.0038972834
B21: 44866 | C21: 63099.65 | D21: =C21/C20-1 -> 0.038735672 | E21: 3762 | F21: =E21/E20-1 -> -0.02109002 | H21: Total | I21: 59 | J21: 0.22753524
B22: 44896 | C22: 60840.74 | D22: =C22/C21-1 -> -0.035799089 | E22: 4379.75 | F22: =E22/E21-1 -> 0.16420787
B23: 44927 | C23: 59549.9 | D23: =C23/C22-1 -> -0.021216704 | E23: 4379.8 | F23: =E23/E22-1 -> 1.1416177e-05 | I23: Coefficients | J23: Standard Error | K23: t Stat | L23: P-value | M23: Lower 95% | N23: Upper 95% | O23: Lower 95.0% | P23: Upper 95.0%
B24: 44958 | C24: 58962.12 | D24: =C24/C23-1 -> -0.0098703776 | E24: 4354.95 | F24: =E24/E23-1 -> -0.0056737751 | H24: Intercept | I24: 0.0072287281 | J24: 0.0081158217 | K24: 0.89069578 | L24: 0.37677236 | M24: -0.0090168541 | N24: 0.02347431 | O24: -0.0090168541 | P24: 0.02347431
B25: 44986 | C25: 58991.52 | D25: =C25/C24-1 -> 0.00049862522 | E25: 4445 | F25: =E25/E24-1 -> 0.02067762 | H25: X Variable 1 | I25: -0.13364939 | J25: 0.21594652 | K25: -0.6189004 | L25: 0.53840531 | M25: -0.56591331 | N25: 0.29861454 | O25: -0.56591331 | P25: 0.29861454
B26: 45017 | C26: 61112.44 | D26: =C26/C25-1 -> 0.035952964 | E26: 4324 | F26: =E26/E25-1 -> -0.027221597
B27: 45047 | C27: 62622.24 | D27: =C27/C26-1 -> 0.024705281 | E27: 4553 | F27: =E27/E26-1 -> 0.052960222
B28: 45078 | C28: 64718.56 | D28: =C28/C27-1 -> 0.033475647 | E28: 4679.95 | F28: =E28/E27-1 -> 0.027882715
B29: 45108 | C29: 66527.67 | D29: =C29/C28-1 -> 0.027953496 | E29: 5010.05 | F29: =E29/E28-1 -> 0.070534942
B30: 45139 | C30: 64831.41 | D30: =C30/C29-1 -> -0.02549706 | E30: 4760.1 | F30: =E30/E29-1 -> -0.049889722
B31: 45170 | C31: 65828.41 | D31: =C31/C30-1 -> 0.015378348 | E31: 4475 | F31: =E31/E30-1 -> -0.0598937
B32: 45200 | C32: 63874.93 | D32: =C32/C31-1 -> -0.029675333 | E32: 4535.25 | F32: =E32/E31-1 -> 0.013463687
B33: 45231 | C33: 66988.44 | D33: =C33/C32-1 -> 0.04874385 | E33: 4419.55 | F33: =E33/E32-1 -> -0.025511273
B34: 45261 | C34: 72240.26 | D34: =C34/C33-1 -> 0.0783989 | E34: 4862 | F34: =E34/E33-1 -> 0.100112
B35: 45292 | C35: 71752.11 | D35: =C35/C34-1 -> -0.0067573123 | E35: 5290.65 | F35: =E35/E34-1 -> 0.088163307
B36: 45323 | C36: 72500.3 | D36: =C36/C35-1 -> 0.010427429 | E36: 5182.35 | F36: =E36/E35-1 -> -0.020470075
B37: 45352 | C37: 73651.35 | D37: =C37/C36-1 -> 0.015876486 | E37: 4999.5 | F37: =E37/E36-1 -> -0.035283221
... B67: 46266 | C67: 73895.74 | D67: =C67/C66-1 -> -0.039782206 | E67: 5296.85 | F67: =E67/E66-1 -> -0.037382668
